2018-10-31 11:59:27.5927 - error: uncaughtException: Callback was already called. date=Wed Oct 31 2018 11:59:27 GMT+0200 (Финляндия (зима)), pid=2212, uid=null, gid=null, cwd=d:\javascript\asutp-web-vs.code, execPath=C:\Program Files\nodejs\node.exe, version=v8.9.4, argv=[C:\Program Files\nodejs\node.exe, d:\javascript\asutp-web-vs.code\server\consoleScripts\importScheme.js], rss=65601536, heapTotal=41263104, heapUsed=21408832, external=18573022, loadavg=[0, 0, 0], uptime=689798.5795933
Error: Callback was already called.
    at d:\javascript\asutp-web-vs.code\node_modules\async\dist\async.js:955:32
    at getNodeObj (d:\javascript\asutp-web-vs.code\server\consoleScripts\importScheme.js:257:11)
    at DbNodeObj.findOne (d:\javascript\asutp-web-vs.code\server\consoleScripts\importScheme.js:83:5)
    at model.Query.<anonymous> (d:\javascript\asutp-web-vs.code\node_modules\mongoose\lib\model.js:4074:16)
    at d:\javascript\asutp-web-vs.code\node_modules\kareem\index.js:273:21
    at d:\javascript\asutp-web-vs.code\node_modules\kareem\index.js:131:16
    at _combinedTickCallback (internal/process/next_tick.js:131:7)
    at process._tickCallback (internal/process/next_tick.js:180:9)
2018-10-31 11:59:27.5927 - error: uncaughtException: Callback was already called. date=Wed Oct 31 2018 11:59:27 GMT+0200 (Финляндия (зима)), pid=2212, uid=null, gid=null, cwd=d:\javascript\asutp-web-vs.code, execPath=C:\Program Files\nodejs\node.exe, version=v8.9.4, argv=[C:\Program Files\nodejs\node.exe, d:\javascript\asutp-web-vs.code\server\consoleScripts\importScheme.js], rss=66433024, heapTotal=41263104, heapUsed=21834016, external=18574432, loadavg=[0, 0, 0], uptime=689798.5916017
Error: Callback was already called.
    at d:\javascript\asutp-web-vs.code\node_modules\async\dist\async.js:955:32
    at getNodeObj (d:\javascript\asutp-web-vs.code\server\consoleScripts\importScheme.js:257:11)
    at DbNodeObj.findOne (d:\javascript\asutp-web-vs.code\server\consoleScripts\importScheme.js:83:5)
    at model.Query.<anonymous> (d:\javascript\asutp-web-vs.code\node_modules\mongoose\lib\model.js:4074:16)
    at d:\javascript\asutp-web-vs.code\node_modules\kareem\index.js:273:21
    at d:\javascript\asutp-web-vs.code\node_modules\kareem\index.js:131:16
    at _combinedTickCallback (internal/process/next_tick.js:131:7)
    at process._tickCallback (internal/process/next_tick.js:180:9)
2018-10-31 11:59:27.5927 - error: uncaughtException: Callback was already called. date=Wed Oct 31 2018 11:59:27 GMT+0200 (Финляндия (зима)), pid=2212, uid=null, gid=null, cwd=d:\javascript\asutp-web-vs.code, execPath=C:\Program Files\nodejs\node.exe, version=v8.9.4, argv=[C:\Program Files\nodejs\node.exe, d:\javascript\asutp-web-vs.code\server\consoleScripts\importScheme.js], rss=66719744, heapTotal=41263104, heapUsed=22112304, external=18576236, loadavg=[0, 0, 0], uptime=689798.5976067
Error: Callback was already called.
    at d:\javascript\asutp-web-vs.code\node_modules\async\dist\async.js:955:32
    at getNodeObj (d:\javascript\asutp-web-vs.code\server\consoleScripts\importScheme.js:257:11)
    at DbNodeObj.findOne (d:\javascript\asutp-web-vs.code\server\consoleScripts\importScheme.js:83:5)
    at model.Query.<anonymous> (d:\javascript\asutp-web-vs.code\node_modules\mongoose\lib\model.js:4074:16)
    at d:\javascript\asutp-web-vs.code\node_modules\kareem\index.js:273:21
    at d:\javascript\asutp-web-vs.code\node_modules\kareem\index.js:131:16
    at _combinedTickCallback (internal/process/next_tick.js:131:7)
    at process._tickCallback (internal/process/next_tick.js:180:9)
2018-10-31 11:59:27.5927 - error: uncaughtException: Callback was already called. date=Wed Oct 31 2018 11:59:27 GMT+0200 (Финляндия (зима)), pid=2212, uid=null, gid=null, cwd=d:\javascript\asutp-web-vs.code, execPath=C:\Program Files\nodejs\node.exe, version=v8.9.4, argv=[C:\Program Files\nodejs\node.exe, d:\javascript\asutp-web-vs.code\server\consoleScripts\importScheme.js], rss=66981888, heapTotal=41263104, heapUsed=22308296, external=18576236, loadavg=[0, 0, 0], uptime=689798.6036106
Error: Callback was already called.
    at d:\javascript\asutp-web-vs.code\node_modules\async\dist\async.js:955:32
    at getNodeObj (d:\javascript\asutp-web-vs.code\server\consoleScripts\importScheme.js:257:11)
    at DbNodeObj.findOne (d:\javascript\asutp-web-vs.code\server\consoleScripts\importScheme.js:83:5)
    at model.Query.<anonymous> (d:\javascript\asutp-web-vs.code\node_modules\mongoose\lib\model.js:4074:16)
    at d:\javascript\asutp-web-vs.code\node_modules\kareem\index.js:273:21
    at d:\javascript\asutp-web-vs.code\node_modules\kareem\index.js:131:16
    at _combinedTickCallback (internal/process/next_tick.js:131:7)
    at process._tickCallback (internal/process/next_tick.js:180:9)
2018-10-31 11:59:27.5927 - error: uncaughtException: Callback was already called. date=Wed Oct 31 2018 11:59:27 GMT+0200 (Финляндия (зима)), pid=2212, uid=null, gid=null, cwd=d:\javascript\asutp-web-vs.code, execPath=C:\Program Files\nodejs\node.exe, version=v8.9.4, argv=[C:\Program Files\nodejs\node.exe, d:\javascript\asutp-web-vs.code\server\consoleScripts\importScheme.js], rss=67051520, heapTotal=41263104, heapUsed=22377312, external=18576236, loadavg=[0, 0, 0], uptime=689798.6046111
Error: Callback was already called.
    at d:\javascript\asutp-web-vs.code\node_modules\async\dist\async.js:955:32
    at checkIfParentNodeExists (d:\javascript\asutp-web-vs.code\server\consoleScripts\importScheme.js:174:7)
    at getNode (d:\javascript\asutp-web-vs.code\server\consoleScripts\importScheme.js:228:11)
    at DbNode.findOne (d:\javascript\asutp-web-vs.code\server\consoleScripts\importScheme.js:75:5)
    at model.Query.<anonymous> (d:\javascript\asutp-web-vs.code\node_modules\mongoose\lib\model.js:4074:16)
    at d:\javascript\asutp-web-vs.code\node_modules\kareem\index.js:273:21
    at d:\javascript\asutp-web-vs.code\node_modules\kareem\index.js:131:16
    at _combinedTickCallback (internal/process/next_tick.js:131:7)
    at Immediate._tickCallback [as _onImmediate] (internal/process/next_tick.js:180:9)
    at runCallback (timers.js:789:20)
    at tryOnImmediate (timers.js:751:5)
    at processImmediate [as _immediateCallback] (timers.js:722:5)
2018-10-31 11:59:27.5927 - error: uncaughtException: Callback was already called. date=Wed Oct 31 2018 11:59:27 GMT+0200 (Финляндия (зима)), pid=2212, uid=null, gid=null, cwd=d:\javascript\asutp-web-vs.code, execPath=C:\Program Files\nodejs\node.exe, version=v8.9.4, argv=[C:\Program Files\nodejs\node.exe, d:\javascript\asutp-web-vs.code\server\consoleScripts\importScheme.js], rss=67137536, heapTotal=41263104, heapUsed=22466160, external=18576236, loadavg=[0, 0, 0], uptime=689798.6066125
Error: Callback was already called.
    at d:\javascript\asutp-web-vs.code\node_modules\async\dist\async.js:955:32
    at getNodeObj (d:\javascript\asutp-web-vs.code\server\consoleScripts\importScheme.js:257:11)
    at DbNodeObj.findOne (d:\javascript\asutp-web-vs.code\server\consoleScripts\importScheme.js:83:5)
    at model.Query.<anonymous> (d:\javascript\asutp-web-vs.code\node_modules\mongoose\lib\model.js:4074:16)
    at d:\javascript\asutp-web-vs.code\node_modules\kareem\index.js:273:21
    at d:\javascript\asutp-web-vs.code\node_modules\kareem\index.js:131:16
    at _combinedTickCallback (internal/process/next_tick.js:131:7)
    at process._tickCallback (internal/process/next_tick.js:180:9)
2018-10-31 11:59:27.5927 - error: uncaughtException: Callback was already called. date=Wed Oct 31 2018 11:59:27 GMT+0200 (Финляндия (зима)), pid=2212, uid=null, gid=null, cwd=d:\javascript\asutp-web-vs.code, execPath=C:\Program Files\nodejs\node.exe, version=v8.9.4, argv=[C:\Program Files\nodejs\node.exe, d:\javascript\asutp-web-vs.code\server\consoleScripts\importScheme.js], rss=67993600, heapTotal=41263104, heapUsed=23318784, external=18590524, loadavg=[0, 0, 0], uptime=689798.6236235
Error: Callback was already called.
    at d:\javascript\asutp-web-vs.code\node_modules\async\dist\async.js:955:32
    at DbNode.findOne (d:\javascript\asutp-web-vs.code\server\consoleScripts\importScheme.js:183:9)
    at model.Query.<anonymous> (d:\javascript\asutp-web-vs.code\node_modules\mongoose\lib\model.js:4074:16)
    at d:\javascript\asutp-web-vs.code\node_modules\kareem\index.js:273:21
    at d:\javascript\asutp-web-vs.code\node_modules\kareem\index.js:131:16
    at _combinedTickCallback (internal/process/next_tick.js:131:7)
    at process._tickCallback (internal/process/next_tick.js:180:9)
2018-10-31 11:59:27.5927 - error: uncaughtException: Callback was already called. date=Wed Oct 31 2018 11:59:27 GMT+0200 (Финляндия (зима)), pid=2212, uid=null, gid=null, cwd=d:\javascript\asutp-web-vs.code, execPath=C:\Program Files\nodejs\node.exe, version=v8.9.4, argv=[C:\Program Files\nodejs\node.exe, d:\javascript\asutp-web-vs.code\server\consoleScripts\importScheme.js], rss=68059136, heapTotal=41263104, heapUsed=23389976, external=18590524, loadavg=[0, 0, 0], uptime=689798.6256252
Error: Callback was already called.
    at d:\javascript\asutp-web-vs.code\node_modules\async\dist\async.js:955:32
    at DbNode.findOne (d:\javascript\asutp-web-vs.code\server\consoleScripts\importScheme.js:183:9)
    at model.Query.<anonymous> (d:\javascript\asutp-web-vs.code\node_modules\mongoose\lib\model.js:4074:16)
    at d:\javascript\asutp-web-vs.code\node_modules\kareem\index.js:273:21
    at d:\javascript\asutp-web-vs.code\node_modules\kareem\index.js:131:16
    at _combinedTickCallback (internal/process/next_tick.js:131:7)
    at process._tickCallback (internal/process/next_tick.js:180:9)
2018-10-31 11:59:27.5927 - error: uncaughtException: Callback was already called. date=Wed Oct 31 2018 11:59:27 GMT+0200 (Финляндия (зима)), pid=2212, uid=null, gid=null, cwd=d:\javascript\asutp-web-vs.code, execPath=C:\Program Files\nodejs\node.exe, version=v8.9.4, argv=[C:\Program Files\nodejs\node.exe, d:\javascript\asutp-web-vs.code\server\consoleScripts\importScheme.js], rss=68132864, heapTotal=41263104, heapUsed=23465528, external=18590524, loadavg=[0, 0, 0], uptime=689798.6286278
Error: Callback was already called.
    at d:\javascript\asutp-web-vs.code\node_modules\async\dist\async.js:955:32
    at DbNode.findOne (d:\javascript\asutp-web-vs.code\server\consoleScripts\importScheme.js:183:9)
    at model.Query.<anonymous> (d:\javascript\asutp-web-vs.code\node_modules\mongoose\lib\model.js:4074:16)
    at d:\javascript\asutp-web-vs.code\node_modules\kareem\index.js:273:21
    at d:\javascript\asutp-web-vs.code\node_modules\kareem\index.js:131:16
    at _combinedTickCallback (internal/process/next_tick.js:131:7)
    at Immediate._tickCallback [as _onImmediate] (internal/process/next_tick.js:180:9)
    at runCallback (timers.js:789:20)
    at tryOnImmediate (timers.js:751:5)
    at processImmediate [as _immediateCallback] (timers.js:722:5)
2018-10-31 11:59:27.5927 - error: uncaughtException: Callback was already called. date=Wed Oct 31 2018 11:59:27 GMT+0200 (Финляндия (зима)), pid=2212, uid=null, gid=null, cwd=d:\javascript\asutp-web-vs.code, execPath=C:\Program Files\nodejs\node.exe, version=v8.9.4, argv=[C:\Program Files\nodejs\node.exe, d:\javascript\asutp-web-vs.code\server\consoleScripts\importScheme.js], rss=68866048, heapTotal=41263104, heapUsed=24028616, external=18602274, loadavg=[0, 0, 0], uptime=689798.6406351
Error: Callback was already called.
    at d:\javascript\asutp-web-vs.code\node_modules\async\dist\async.js:955:32
    at DbNode.findOne (d:\javascript\asutp-web-vs.code\server\consoleScripts\importScheme.js:183:9)
    at model.Query.<anonymous> (d:\javascript\asutp-web-vs.code\node_modules\mongoose\lib\model.js:4074:16)
    at d:\javascript\asutp-web-vs.code\node_modules\kareem\index.js:273:21
    at d:\javascript\asutp-web-vs.code\node_modules\kareem\index.js:131:16
    at _combinedTickCallback (internal/process/next_tick.js:131:7)
    at process._tickCallback (internal/process/next_tick.js:180:9)
2018-10-31 11:59:27.5927 - error: uncaughtException: Callback was already called. date=Wed Oct 31 2018 11:59:27 GMT+0200 (Финляндия (зима)), pid=2212, uid=null, gid=null, cwd=d:\javascript\asutp-web-vs.code, execPath=C:\Program Files\nodejs\node.exe, version=v8.9.4, argv=[C:\Program Files\nodejs\node.exe, d:\javascript\asutp-web-vs.code\server\consoleScripts\importScheme.js], rss=68939776, heapTotal=41263104, heapUsed=24104464, external=18602274, loadavg=[0, 0, 0], uptime=689798.6436383
Error: Callback was already called.
    at d:\javascript\asutp-web-vs.code\node_modules\async\dist\async.js:955:32
    at DbNode.findOne (d:\javascript\asutp-web-vs.code\server\consoleScripts\importScheme.js:183:9)
    at model.Query.<anonymous> (d:\javascript\asutp-web-vs.code\node_modules\mongoose\lib\model.js:4074:16)
    at d:\javascript\asutp-web-vs.code\node_modules\kareem\index.js:273:21
    at d:\javascript\asutp-web-vs.code\node_modules\kareem\index.js:131:16
    at _combinedTickCallback (internal/process/next_tick.js:131:7)
    at Immediate._tickCallback [as _onImmediate] (internal/process/next_tick.js:180:9)
    at runCallback (timers.js:789:20)
    at tryOnImmediate (timers.js:751:5)
    at processImmediate [as _immediateCallback] (timers.js:722:5)
2018-10-31 11:59:27.5927 - error: uncaughtException: Callback was already called. date=Wed Oct 31 2018 11:59:27 GMT+0200 (Финляндия (зима)), pid=2212, uid=null, gid=null, cwd=d:\javascript\asutp-web-vs.code, execPath=C:\Program Files\nodejs\node.exe, version=v8.9.4, argv=[C:\Program Files\nodejs\node.exe, d:\javascript\asutp-web-vs.code\server\consoleScripts\importScheme.js], rss=69029888, heapTotal=41263104, heapUsed=24193152, external=18602274, loadavg=[0, 0, 0], uptime=689798.6466396
Error: Callback was already called.
    at d:\javascript\asutp-web-vs.code\node_modules\async\dist\async.js:955:32
    at DbNode.findOne (d:\javascript\asutp-web-vs.code\server\consoleScripts\importScheme.js:183:9)
    at model.Query.<anonymous> (d:\javascript\asutp-web-vs.code\node_modules\mongoose\lib\model.js:4074:16)
    at d:\javascript\asutp-web-vs.code\node_modules\kareem\index.js:273:21
    at d:\javascript\asutp-web-vs.code\node_modules\kareem\index.js:131:16
    at _combinedTickCallback (internal/process/next_tick.js:131:7)
    at process._tickCallback (internal/process/next_tick.js:180:9)
2018-10-31 11:59:27.5927 - error: uncaughtException: Callback was already called. date=Wed Oct 31 2018 11:59:27 GMT+0200 (Финляндия (зима)), pid=2212, uid=null, gid=null, cwd=d:\javascript\asutp-web-vs.code, execPath=C:\Program Files\nodejs\node.exe, version=v8.9.4, argv=[C:\Program Files\nodejs\node.exe, d:\javascript\asutp-web-vs.code\server\consoleScripts\importScheme.js], rss=70901760, heapTotal=42835968, heapUsed=18720384, external=17863102, loadavg=[0, 0, 0], uptime=689798.664653
Error: Callback was already called.
    at d:\javascript\asutp-web-vs.code\node_modules\async\dist\async.js:955:32
    at DbNode.findOne (d:\javascript\asutp-web-vs.code\server\consoleScripts\importScheme.js:183:9)
    at model.Query.<anonymous> (d:\javascript\asutp-web-vs.code\node_modules\mongoose\lib\model.js:4074:16)
    at d:\javascript\asutp-web-vs.code\node_modules\kareem\index.js:273:21
    at d:\javascript\asutp-web-vs.code\node_modules\kareem\index.js:131:16
    at _combinedTickCallback (internal/process/next_tick.js:131:7)
    at process._tickCallback (internal/process/next_tick.js:180:9)
2018-10-31 11:59:27.5927 - error: uncaughtException: Callback was already called. date=Wed Oct 31 2018 11:59:27 GMT+0200 (Финляндия (зима)), pid=2212, uid=null, gid=null, cwd=d:\javascript\asutp-web-vs.code, execPath=C:\Program Files\nodejs\node.exe, version=v8.9.4, argv=[C:\Program Files\nodejs\node.exe, d:\javascript\asutp-web-vs.code\server\consoleScripts\importScheme.js], rss=70901760, heapTotal=42835968, heapUsed=18796232, external=17863102, loadavg=[0, 0, 0], uptime=689798.6666542
Error: Callback was already called.
    at d:\javascript\asutp-web-vs.code\node_modules\async\dist\async.js:955:32
    at DbNode.findOne (d:\javascript\asutp-web-vs.code\server\consoleScripts\importScheme.js:183:9)
    at model.Query.<anonymous> (d:\javascript\asutp-web-vs.code\node_modules\mongoose\lib\model.js:4074:16)
    at d:\javascript\asutp-web-vs.code\node_modules\kareem\index.js:273:21
    at d:\javascript\asutp-web-vs.code\node_modules\kareem\index.js:131:16
    at _combinedTickCallback (internal/process/next_tick.js:131:7)
    at Immediate._tickCallback [as _onImmediate] (internal/process/next_tick.js:180:9)
    at runCallback (timers.js:789:20)
    at tryOnImmediate (timers.js:751:5)
    at processImmediate [as _immediateCallback] (timers.js:722:5)
2018-10-31 11:59:27.5927 - error: uncaughtException: Callback was already called. date=Wed Oct 31 2018 11:59:27 GMT+0200 (Финляндия (зима)), pid=2212, uid=null, gid=null, cwd=d:\javascript\asutp-web-vs.code, execPath=C:\Program Files\nodejs\node.exe, version=v8.9.4, argv=[C:\Program Files\nodejs\node.exe, d:\javascript\asutp-web-vs.code\server\consoleScripts\importScheme.js], rss=70901760, heapTotal=42835968, heapUsed=18877488, external=17863102, loadavg=[0, 0, 0], uptime=689798.6686558
Error: Callback was already called.
    at d:\javascript\asutp-web-vs.code\node_modules\async\dist\async.js:955:32
    at DbNode.findOne (d:\javascript\asutp-web-vs.code\server\consoleScripts\importScheme.js:183:9)
    at model.Query.<anonymous> (d:\javascript\asutp-web-vs.code\node_modules\mongoose\lib\model.js:4074:16)
    at d:\javascript\asutp-web-vs.code\node_modules\kareem\index.js:273:21
    at d:\javascript\asutp-web-vs.code\node_modules\kareem\index.js:131:16
    at _combinedTickCallback (internal/process/next_tick.js:131:7)
    at process._tickCallback (internal/process/next_tick.js:180:9)
2018-10-31 11:59:27.5927 - error: uncaughtException: Callback was already called. date=Wed Oct 31 2018 11:59:27 GMT+0200 (Финляндия (зима)), pid=2212, uid=null, gid=null, cwd=d:\javascript\asutp-web-vs.code, execPath=C:\Program Files\nodejs\node.exe, version=v8.9.4, argv=[C:\Program Files\nodejs\node.exe, d:\javascript\asutp-web-vs.code\server\consoleScripts\importScheme.js], rss=70918144, heapTotal=42835968, heapUsed=19556440, external=17875632, loadavg=[0, 0, 0], uptime=689798.6826651
Error: Callback was already called.
    at d:\javascript\asutp-web-vs.code\node_modules\async\dist\async.js:955:32
    at DbNode.findOne (d:\javascript\asutp-web-vs.code\server\consoleScripts\importScheme.js:183:9)
    at model.Query.<anonymous> (d:\javascript\asutp-web-vs.code\node_modules\mongoose\lib\model.js:4074:16)
    at d:\javascript\asutp-web-vs.code\node_modules\kareem\index.js:273:21
    at d:\javascript\asutp-web-vs.code\node_modules\kareem\index.js:131:16
    at _combinedTickCallback (internal/process/next_tick.js:131:7)
    at process._tickCallback (internal/process/next_tick.js:180:9)
2018-10-31 11:59:27.5927 - error: uncaughtException: Callback was already called. date=Wed Oct 31 2018 11:59:27 GMT+0200 (Финляндия (зима)), pid=2212, uid=null, gid=null, cwd=d:\javascript\asutp-web-vs.code, execPath=C:\Program Files\nodejs\node.exe, version=v8.9.4, argv=[C:\Program Files\nodejs\node.exe, d:\javascript\asutp-web-vs.code\server\consoleScripts\importScheme.js], rss=70918144, heapTotal=42835968, heapUsed=19624208, external=17875632, loadavg=[0, 0, 0], uptime=689798.6846673
Error: Callback was already called.
    at d:\javascript\asutp-web-vs.code\node_modules\async\dist\async.js:955:32
    at DbNode.findOne (d:\javascript\asutp-web-vs.code\server\consoleScripts\importScheme.js:183:9)
    at model.Query.<anonymous> (d:\javascript\asutp-web-vs.code\node_modules\mongoose\lib\model.js:4074:16)
    at d:\javascript\asutp-web-vs.code\node_modules\kareem\index.js:273:21
    at d:\javascript\asutp-web-vs.code\node_modules\kareem\index.js:131:16
    at _combinedTickCallback (internal/process/next_tick.js:131:7)
    at process._tickCallback (internal/process/next_tick.js:180:9)
2018-10-31 11:59:27.5927 - error: uncaughtException: Callback was already called. date=Wed Oct 31 2018 11:59:27 GMT+0200 (Финляндия (зима)), pid=2212, uid=null, gid=null, cwd=d:\javascript\asutp-web-vs.code, execPath=C:\Program Files\nodejs\node.exe, version=v8.9.4, argv=[C:\Program Files\nodejs\node.exe, d:\javascript\asutp-web-vs.code\server\consoleScripts\importScheme.js], rss=70918144, heapTotal=42835968, heapUsed=19691416, external=17875632, loadavg=[0, 0, 0], uptime=689798.6856672
Error: Callback was already called.
    at d:\javascript\asutp-web-vs.code\node_modules\async\dist\async.js:955:32
    at DbNode.findOne (d:\javascript\asutp-web-vs.code\server\consoleScripts\importScheme.js:183:9)
    at model.Query.<anonymous> (d:\javascript\asutp-web-vs.code\node_modules\mongoose\lib\model.js:4074:16)
    at d:\javascript\asutp-web-vs.code\node_modules\kareem\index.js:273:21
    at d:\javascript\asutp-web-vs.code\node_modules\kareem\index.js:131:16
    at _combinedTickCallback (internal/process/next_tick.js:131:7)
    at Immediate._tickCallback [as _onImmediate] (internal/process/next_tick.js:180:9)
    at runCallback (timers.js:789:20)
    at tryOnImmediate (timers.js:751:5)
    at processImmediate [as _immediateCallback] (timers.js:722:5)
2018-10-31 11:59:27.5927 - error: uncaughtException: Callback was already called. date=Wed Oct 31 2018 11:59:27 GMT+0200 (Финляндия (зима)), pid=2212, uid=null, gid=null, cwd=d:\javascript\asutp-web-vs.code, execPath=C:\Program Files\nodejs\node.exe, version=v8.9.4, argv=[C:\Program Files\nodejs\node.exe, d:\javascript\asutp-web-vs.code\server\consoleScripts\importScheme.js], rss=71032832, heapTotal=42835968, heapUsed=20648456, external=17881901, loadavg=[0, 0, 0], uptime=689798.7086833
Error: Callback was already called.
    at d:\javascript\asutp-web-vs.code\node_modules\async\dist\async.js:955:32
    at DbNode.findOne (d:\javascript\asutp-web-vs.code\server\consoleScripts\importScheme.js:183:9)
    at model.Query.<anonymous> (d:\javascript\asutp-web-vs.code\node_modules\mongoose\lib\model.js:4074:16)
    at d:\javascript\asutp-web-vs.code\node_modules\kareem\index.js:273:21
    at d:\javascript\asutp-web-vs.code\node_modules\kareem\index.js:131:16
    at _combinedTickCallback (internal/process/next_tick.js:131:7)
    at process._tickCallback (internal/process/next_tick.js:180:9)
2018-10-31 11:59:27.5927 - error: uncaughtException: Callback was already called. date=Wed Oct 31 2018 11:59:27 GMT+0200 (Финляндия (зима)), pid=2212, uid=null, gid=null, cwd=d:\javascript\asutp-web-vs.code, execPath=C:\Program Files\nodejs\node.exe, version=v8.9.4, argv=[C:\Program Files\nodejs\node.exe, d:\javascript\asutp-web-vs.code\server\consoleScripts\importScheme.js], rss=71032832, heapTotal=42835968, heapUsed=20726224, external=17881901, loadavg=[0, 0, 0], uptime=689798.7136879
Error: Callback was already called.
    at d:\javascript\asutp-web-vs.code\node_modules\async\dist\async.js:955:32
    at DbNode.findOne (d:\javascript\asutp-web-vs.code\server\consoleScripts\importScheme.js:183:9)
    at model.Query.<anonymous> (d:\javascript\asutp-web-vs.code\node_modules\mongoose\lib\model.js:4074:16)
    at d:\javascript\asutp-web-vs.code\node_modules\kareem\index.js:273:21
    at d:\javascript\asutp-web-vs.code\node_modules\kareem\index.js:131:16
    at _combinedTickCallback (internal/process/next_tick.js:131:7)
    at Immediate._tickCallback [as _onImmediate] (internal/process/next_tick.js:180:9)
    at runCallback (timers.js:789:20)
    at tryOnImmediate (timers.js:751:5)
    at processImmediate [as _immediateCallback] (timers.js:722:5)
2018-10-31 11:59:27.5927 - error: uncaughtException: Callback was already called. date=Wed Oct 31 2018 11:59:27 GMT+0200 (Финляндия (зима)), pid=2212, uid=null, gid=null, cwd=d:\javascript\asutp-web-vs.code, execPath=C:\Program Files\nodejs\node.exe, version=v8.9.4, argv=[C:\Program Files\nodejs\node.exe, d:\javascript\asutp-web-vs.code\server\consoleScripts\importScheme.js], rss=71036928, heapTotal=42835968, heapUsed=20815688, external=17881901, loadavg=[0, 0, 0], uptime=689798.7156882
Error: Callback was already called.
    at d:\javascript\asutp-web-vs.code\node_modules\async\dist\async.js:955:32
    at DbNode.findOne (d:\javascript\asutp-web-vs.code\server\consoleScripts\importScheme.js:183:9)
    at model.Query.<anonymous> (d:\javascript\asutp-web-vs.code\node_modules\mongoose\lib\model.js:4074:16)
    at d:\javascript\asutp-web-vs.code\node_modules\kareem\index.js:273:21
    at d:\javascript\asutp-web-vs.code\node_modules\kareem\index.js:131:16
    at _combinedTickCallback (internal/process/next_tick.js:131:7)
    at process._tickCallback (internal/process/next_tick.js:180:9)
2018-10-31 11:59:27.5927 - error: uncaughtException: Callback was already called. date=Wed Oct 31 2018 11:59:27 GMT+0200 (Финляндия (зима)), pid=2212, uid=null, gid=null, cwd=d:\javascript\asutp-web-vs.code, execPath=C:\Program Files\nodejs\node.exe, version=v8.9.4, argv=[C:\Program Files\nodejs\node.exe, d:\javascript\asutp-web-vs.code\server\consoleScripts\importScheme.js], rss=71036928, heapTotal=42835968, heapUsed=20892232, external=17890093, loadavg=[0, 0, 0], uptime=689798.7166892
Error: Callback was already called.
    at d:\javascript\asutp-web-vs.code\node_modules\async\dist\async.js:955:32
    at DbNode.findOne (d:\javascript\asutp-web-vs.code\server\consoleScripts\importScheme.js:183:9)
    at model.Query.<anonymous> (d:\javascript\asutp-web-vs.code\node_modules\mongoose\lib\model.js:4074:16)
    at d:\javascript\asutp-web-vs.code\node_modules\kareem\index.js:273:21
    at d:\javascript\asutp-web-vs.code\node_modules\kareem\index.js:131:16
    at _combinedTickCallback (internal/process/next_tick.js:131:7)
    at Immediate._tickCallback [as _onImmediate] (internal/process/next_tick.js:180:9)
    at runCallback (timers.js:789:20)
    at tryOnImmediate (timers.js:751:5)
    at processImmediate [as _immediateCallback] (timers.js:722:5)
2018-10-31 11:59:27.5927 - error: uncaughtException: Callback was already called. date=Wed Oct 31 2018 11:59:27 GMT+0200 (Финляндия (зима)), pid=2212, uid=null, gid=null, cwd=d:\javascript\asutp-web-vs.code, execPath=C:\Program Files\nodejs\node.exe, version=v8.9.4, argv=[C:\Program Files\nodejs\node.exe, d:\javascript\asutp-web-vs.code\server\consoleScripts\importScheme.js], rss=71888896, heapTotal=42835968, heapUsed=21941912, external=17897171, loadavg=[0, 0, 0], uptime=689798.7367026
Error: Callback was already called.
    at d:\javascript\asutp-web-vs.code\node_modules\async\dist\async.js:955:32
    at DbNode.findOne (d:\javascript\asutp-web-vs.code\server\consoleScripts\importScheme.js:183:9)
    at model.Query.<anonymous> (d:\javascript\asutp-web-vs.code\node_modules\mongoose\lib\model.js:4074:16)
    at d:\javascript\asutp-web-vs.code\node_modules\kareem\index.js:273:21
    at d:\javascript\asutp-web-vs.code\node_modules\kareem\index.js:131:16
    at _combinedTickCallback (internal/process/next_tick.js:131:7)
    at process._tickCallback (internal/process/next_tick.js:180:9)
2018-10-31 11:59:27.5927 - error: uncaughtException: Callback was already called. date=Wed Oct 31 2018 11:59:27 GMT+0200 (Финляндия (зима)), pid=2212, uid=null, gid=null, cwd=d:\javascript\asutp-web-vs.code, execPath=C:\Program Files\nodejs\node.exe, version=v8.9.4, argv=[C:\Program Files\nodejs\node.exe, d:\javascript\asutp-web-vs.code\server\consoleScripts\importScheme.js], rss=71888896, heapTotal=42835968, heapUsed=22026032, external=17897171, loadavg=[0, 0, 0], uptime=689798.7377039
Error: Callback was already called.
    at d:\javascript\asutp-web-vs.code\node_modules\async\dist\async.js:955:32
    at DbNode.findOne (d:\javascript\asutp-web-vs.code\server\consoleScripts\importScheme.js:183:9)
    at model.Query.<anonymous> (d:\javascript\asutp-web-vs.code\node_modules\mongoose\lib\model.js:4074:16)
    at d:\javascript\asutp-web-vs.code\node_modules\kareem\index.js:273:21
    at d:\javascript\asutp-web-vs.code\node_modules\kareem\index.js:131:16
    at _combinedTickCallback (internal/process/next_tick.js:131:7)
    at Immediate._tickCallback [as _onImmediate] (internal/process/next_tick.js:180:9)
    at runCallback (timers.js:789:20)
    at tryOnImmediate (timers.js:751:5)
    at processImmediate [as _immediateCallback] (timers.js:722:5)
2018-10-31 11:59:27.5927 - error: uncaughtException: Callback was already called. date=Wed Oct 31 2018 11:59:27 GMT+0200 (Финляндия (зима)), pid=2212, uid=null, gid=null, cwd=d:\javascript\asutp-web-vs.code, execPath=C:\Program Files\nodejs\node.exe, version=v8.9.4, argv=[C:\Program Files\nodejs\node.exe, d:\javascript\asutp-web-vs.code\server\consoleScripts\importScheme.js], rss=71888896, heapTotal=42835968, heapUsed=22114688, external=17897171, loadavg=[0, 0, 0], uptime=689798.7387043
Error: Callback was already called.
    at d:\javascript\asutp-web-vs.code\node_modules\async\dist\async.js:955:32
    at DbNode.findOne (d:\javascript\asutp-web-vs.code\server\consoleScripts\importScheme.js:183:9)
    at model.Query.<anonymous> (d:\javascript\asutp-web-vs.code\node_modules\mongoose\lib\model.js:4074:16)
    at d:\javascript\asutp-web-vs.code\node_modules\kareem\index.js:273:21
    at d:\javascript\asutp-web-vs.code\node_modules\kareem\index.js:131:16
    at _combinedTickCallback (internal/process/next_tick.js:131:7)
    at process._tickCallback (internal/process/next_tick.js:180:9)
2018-10-31 11:59:27.5927 - error: uncaughtException: Callback was already called. date=Wed Oct 31 2018 11:59:27 GMT+0200 (Финляндия (зима)), pid=2212, uid=null, gid=null, cwd=d:\javascript\asutp-web-vs.code, execPath=C:\Program Files\nodejs\node.exe, version=v8.9.4, argv=[C:\Program Files\nodejs\node.exe, d:\javascript\asutp-web-vs.code\server\consoleScripts\importScheme.js], rss=71888896, heapTotal=42835968, heapUsed=22190360, external=17897171, loadavg=[0, 0, 0], uptime=689798.7407062
Error: Callback was already called.
    at d:\javascript\asutp-web-vs.code\node_modules\async\dist\async.js:955:32
    at DbNode.findOne (d:\javascript\asutp-web-vs.code\server\consoleScripts\importScheme.js:183:9)
    at model.Query.<anonymous> (d:\javascript\asutp-web-vs.code\node_modules\mongoose\lib\model.js:4074:16)
    at d:\javascript\asutp-web-vs.code\node_modules\kareem\index.js:273:21
    at d:\javascript\asutp-web-vs.code\node_modules\kareem\index.js:131:16
    at _combinedTickCallback (internal/process/next_tick.js:131:7)
    at Immediate._tickCallback [as _onImmediate] (internal/process/next_tick.js:180:9)
    at runCallback (timers.js:789:20)
    at tryOnImmediate (timers.js:751:5)
    at processImmediate [as _immediateCallback] (timers.js:722:5)
2018-10-31 11:59:27.5927 - error: uncaughtException: Callback was already called. date=Wed Oct 31 2018 11:59:27 GMT+0200 (Финляндия (зима)), pid=2212, uid=null, gid=null, cwd=d:\javascript\asutp-web-vs.code, execPath=C:\Program Files\nodejs\node.exe, version=v8.9.4, argv=[C:\Program Files\nodejs\node.exe, d:\javascript\asutp-web-vs.code\server\consoleScripts\importScheme.js], rss=71888896, heapTotal=42835968, heapUsed=22279376, external=17897171, loadavg=[0, 0, 0], uptime=689798.7417067
Error: Callback was already called.
    at d:\javascript\asutp-web-vs.code\node_modules\async\dist\async.js:955:32
    at DbNode.findOne (d:\javascript\asutp-web-vs.code\server\consoleScripts\importScheme.js:183:9)
    at model.Query.<anonymous> (d:\javascript\asutp-web-vs.code\node_modules\mongoose\lib\model.js:4074:16)
    at d:\javascript\asutp-web-vs.code\node_modules\kareem\index.js:273:21
    at d:\javascript\asutp-web-vs.code\node_modules\kareem\index.js:131:16
    at _combinedTickCallback (internal/process/next_tick.js:131:7)
    at process._tickCallback (internal/process/next_tick.js:180:9)
2018-10-31 11:59:27.5927 - error: uncaughtException: Callback was already called. date=Wed Oct 31 2018 11:59:27 GMT+0200 (Финляндия (зима)), pid=2212, uid=null, gid=null, cwd=d:\javascript\asutp-web-vs.code, execPath=C:\Program Files\nodejs\node.exe, version=v8.9.4, argv=[C:\Program Files\nodejs\node.exe, d:\javascript\asutp-web-vs.code\server\consoleScripts\importScheme.js], rss=71905280, heapTotal=42835968, heapUsed=22398568, external=17905363, loadavg=[0, 0, 0], uptime=689798.7507147
Error: Callback was already called.
    at d:\javascript\asutp-web-vs.code\node_modules\async\dist\async.js:955:32
    at DbNode.findOne (d:\javascript\asutp-web-vs.code\server\consoleScripts\importScheme.js:183:9)
    at model.Query.<anonymous> (d:\javascript\asutp-web-vs.code\node_modules\mongoose\lib\model.js:4074:16)
    at d:\javascript\asutp-web-vs.code\node_modules\kareem\index.js:273:21
    at d:\javascript\asutp-web-vs.code\node_modules\kareem\index.js:131:16
    at _combinedTickCallback (internal/process/next_tick.js:131:7)
    at Immediate._tickCallback [as _onImmediate] (internal/process/next_tick.js:180:9)
    at runCallback (timers.js:789:20)
    at tryOnImmediate (timers.js:751:5)
    at processImmediate [as _immediateCallback] (timers.js:722:5)
